Workbook

Sheet Failure Mode Table
B3: Event rate per year' is the county-wide (or system-level) rate lambda unless the Rate basis column says otherwise. F = lambda/8760 (your original convention). G = F x area scaling factor 0.0831 for area-distributed hazards; per-customer power indices are already per node, so G = F. N = P(>=1 event in an hour) = 1 - exp(-H). Q/R: per-edge (or per-node) hourly rate = H divided by the number of applicable edges from the Assumptions sheet (15 edges assumed; 9 freeway, 4 WUI, 1 SFHA). AV share: change Assumptions!C9 only - rows 1-3 scale by (1 - C9), rows 4-6 by C9. Evidence status: Empirical = number taken directly from a source; Derived = computed from sourced inputs (formula shown); Assumption = judgement; GAP = no defensible source found.
B5: Number | C5: Hazard | D5: Type | E5: Severity | F5: Event rate per year (lambda) | G5: P per hour (before scaling) = lambda/8760 | H5: P per hour (after scaling) | I5: Duration | J5: Source | K5: Notes | L5: Rate basis / unit | M5: Scaling applied | N5: P(>=1 event in hour) after scaling = 1-exp(-G) | O5: Evidence status | P5: Duration basis | Q5: Applicable edges (count, from Assumptions) | R5: P per hour PER EDGE (or per node) after scaling = H / Q | S5: Priority | T5: Feasibility
B6: 1 | C6: Traffic incident - human driver (crash + non-crash: disablement, debris/spill, stall) | D6: edge | E6: low - reduced capacity (shoulder or <= 1 lane) | F6: =Assumptions!$C$15/(1-Assumptions!$C$14)/Assumptions!$C$31*Assumptions!$C$30-F9-F10 -> 698222.07 | G6: =F6/Assumptions!$C$7 -> 79.705716 | H6: =G6*Assumptions!$C$6 -> 6.6233304 | I6: 0.25-0.4 h. LA FSP FY2020-21 average on-scene assist time 15.1 min (collision 24.4, mechanical 18.8, flat 17.8, debris 10.4, out of gas 12.4 min) + ~2.5-10 min wait for the truck; Caltrans 2025 manual: minor incidents < 30 min. Giuliano 1989 (37 min mean incl. detection) is an upper bound. | J6: California FSP MIS Annual Report FY2020-21 (Mauch & Skabardonis 2022), Los Angeles tables [S58]; Metro OIG FSP review 2020 [S59]; Caltrans Traffic Ops Manual Ch.130 (2025) duration classes [S61]; PeMS CHP incidents Q1 2025 (user export) [S62]; Caltrans 2022 Crash Data, LA County [S2]; TIMS county totals via [S3]; Giuliano 1989 (secondary) [S1]; Lindley/Goolsby capacity-loss table via ROSAP DOT-26855 [S54]. | K6: TIERS ARE MUTUALLY EXCLUSIVE: lambda_1 = (all reported incidents) - lambda_2 - lambda_3, so an incident is counted in exactly one of rows 1-3. All reported incidents = police-reported crashes (40,449 F+I / (1-0.666 PDO share) = 121,000) / 0.164 (collision share of LA FSP assists, FY2020-21) x human VMT share -> ~0.70 M/yr county-wide (was ~1.05 M with Giuliano 1989's 11%); rows 2-3 remove only ~3,100 of these (0.4%). WHAT IS IN ROW 1: (a) every non-fatal crash (PDO or injury) that does NOT block a lane for >= 30 min - i.e. shoulder-only crashes (59% of freeway crashes) and short lane blockages (most of the remaining 41%: mean lane-closing crash duration 38-66 min but the SigAlert count captures only those the CHP declares); (b) all non-crash incidents (disablements 80%, debris/spills/pedestrians/police 9%) that are not SigAlerts. NOT in row 1: SigAlert-class blockages (row 2) and fatal crashes (row 3). Cross-checks (freeways carry ~50% of VMT, so row 1 implies ~350,000 freeway incidents/yr): PeMS CHP-logged incidents, District 7, 2025 (Q1+Q3+Q4; Q2 is a data gap) = 4.08 per MVMT -> ~145,000/yr on LA freeways (LOWER bound - CHP logs only); LA FSP 237,752 assists in FY2020-21 during service hours only; I-880 probe study ~100 incidents/MVMT incl. unreported short stops (upper bound, 3.5 M/yr). Capacity effect (Lindley 1986 table): shoulder disablement keeps 0.95-0.99 of capacity, shoulder crash 0.81-0.93, one lane blocked 0.35-0.78 (2-8 directional lanes), two lanes blocked 0.00-0.63; Goolsby: 1 of 3 lanes blocked = -50% capacity. Split for simulation: ~90% of incidents are shoulder-only (capacity x0.81-0.99), ~10% in a travel lane (x0.35-0.78; Assumptions C32 = LA FSP 10.3%; range 4-18%). Recurring congestion is NOT in this row - see row 1c. After scaling, ~6.6 events/h in the model area (~0.44/h per edge with 15 edges) -> sample count per hour from Poisson. | L6: county-wide reported incidents / yr (all roads, all types) | M6: x area factor (0.0831) | N6: =IF(ISNUMBER(H6),1-EXP(-H6),"n/a") -> 0.998671 | O6: Derived | P6: Empirical (LA FSP FY2020-21 on-scene times) | Q6: =Assumptions!$C$37 -> 15 | R6: =IF(ISNUMBER(H6),H6/Q6,"n/a") -> 0.44155536
B7: 1b | C7: Weather - rain day (reduced capacity on all edges; 2-3x incident rate) | D7: all edges (regional, same day) | E7: low - reduced capacity, elevated incident rate | F7: =Assumptions!$C$33 -> 34.1 | G7: =F7/Assumptions!$C$7 -> 0.0038926941 | H7: =G7 -> 0.0038926941 | I7: Rain-day: treat as 6-24 h per event (34 rain days/yr but ~15 in of rain -> most days are light, a few hours of rain). Nov-Apr carries 95% of rainfall. | J7: NOAA 1991-2020 normals, downtown LA: 34.1 days/yr >= 0.01 in [S48]; Skabardonis et al. 1995: 3.5 accidents/shift on rainy days vs 1.5 clear (I-880) [S4]; FHWA: bad weather = 15% of congestion [S49]; LA County Hazard Mitigation Plan (95% of rain Nov-Apr) [S52]. | K7: Rain is a REGIONAL common-cause event: on a rain day every edge loses some capacity and incident rows 1-6 should be multiplied by ~2-3 (I-880: 2.3x accidents per shift on rainy days). Not area-scaled (weather covers the whole model region). Capacity/speed reductions for rain are tabulated in HCM 2010 Ch. 10/11 weather adjustment factors (not extracted here - GAP for exact CAF values). Seasonality: concentrate the 34 days in Nov-Apr (LA County: 95% of rain in that window). | L7: rain days / yr (downtown LA normals) | M7: none (per-edge or per-fleet basis; see notes) | N7: =IF(ISNUMBER(H7),1-EXP(-H7),"n/a") -> 0.0038851274 | O7: Empirical (frequency) / Assumption (duration, multiplier) | P7: Assumption | Q7: n/a (system / regional / fleet event) | R7: =H7 -> 0.0038926941
B8: 1c | C8: Recurring congestion / bottlenecks (deterministic, not a random failure) | D8: edge (freeway edges in peak) | E8: low - reduced speed/capacity, scheduled | F8: n/a (deterministic) | G8: n/a | H8: n/a | I8: Weekday AM (6-10) and PM (15-19) peaks; Caltrans D7 Q1 2022: 23 million vehicle-hours of delay, 98% in LA County, on 8.5 billion freeway VMT per quarter. | J8: FHWA sources of congestion: bottlenecks 40%, incidents 25%, weather 15%, work zones 10%, signals 5%, events 5% [S49]; Caltrans District 7 Mobility Performance Report Q1 2022 [S50]; Caltrans PeMS for edge-level speed profiles (not extracted). | K8: Not a stochastic failure mode, so no lambda: recurring congestion is 40% of US congestion (FHWA) and is predictable by time of day. Recommend a deterministic hourly capacity/speed profile per freeway edge from Caltrans PeMS, and let rows 1, 1b, 2-6 be the random component on top of it. If you must have a rate: every weekday peak hour on every freeway edge (~2,000 h/yr per edge, P = 1 in those hours). | L8: deterministic time-of-day profile | M8: n/a | N8: n/a | O8: Empirical (nature) - no rate needed | P8: Empirical (Caltrans D7 MPR) | Q8: all freeway edges | R8: n/a
B9: 2 | C9: Traffic incident - human driver | D9: edge | E9: mid - no capacity | F9: =(Assumptions!$C$17-Assumptions!$C$46)*Assumptions!$C$30 -> 2189.75 | G9: =F9/Assumptions!$C$7 -> 0.24997146 | H9: =G9*Assumptions!$C$6 -> 0.020771956 | I9: 0.5-2 h, central ~1 h (Caltrans 2025 manual 'intermediate' incident: 30 min-2 h; SigAlert threshold >= 30 min; I-710 big-rig study 58-76 min as a check). | J9: CHP SigAlert counts via Crosstown LA [S5]; Caltrans Traffic Ops Manual Ch.130 (2025) [S61]; I-710 Big Rig FSP evaluation 2005 (secondary) [S6]. | K9: lambda = SigAlerts in LA County (>=1 lane blocked >= 30 min): 2,515 in 2018 (2,239 in 2016), 11 freeways only (I-5 344, US-101 286, I-405 284), MINUS the 210 fatal freeway crashes/yr (Caltrans 2022), which are assumed to always trigger a SigAlert and are counted in row 3 instead -> 2,305 x human share. Row 2 therefore = non-fatal crash AND non-crash (stall, spill, debris, hazmat, police) blockages >= 30 min on freeways. Arterial long blockages have no count and remain inside row 1 (gap). This is 'major lane blockage', not certified full closure; full-direction closures are a subset (Giuliano: 5% of freeway accidents close >=3 lanes, 8% close 2 lanes). Arterials are not covered - SigAlerts are freeway events, so the area scaling assumes freeway density in the model area is the county average. SigAlerts already include NON-CRASH causes (stalled trucks, spilled loads, debris, police activity, flooding), so this row satisfies your request to include non-crash events at the mid-severity level. ~20% of LA County SigAlerts involve trucks (I-710 study: 82%). | L9: county-wide freeway SigAlerts / yr | M9: x area factor (0.0831) | N9: =IF(ISNUMBER(H9),1-EXP(-H9),"n/a") -> 0.020557704 | O9: Empirical | P9: Definitional (Caltrans 2025 intermediate class) / Empirical (I-710 FSP 2005) | Q9: =Assumptions!$C$38 -> 9 | R9: =IF(ISNUMBER(H9),H9/Q9,"n/a") -> 0.0023079951
B10: 3 | C10: Traffic incident - human driver | D10: >=3 edges | E10: high - major closure / diversion | F10: =Assumptions!$C$18*Assumptions!$C$30 -> 904.875 | G10: =F10/Assumptions!$C$7 -> 0.10329623 | H10: =G10*Assumptions!$C$6 -> 0.0085836389 | I10: 3.3 h (Caltrans FY2014-15 statewide major incidents: 3 h 17 min average; fatal 3.1-3.9 h, big rig 3.6-4.8 h, hazmat 3.6-5.6 h). Caltrans 2025 manual: major > 2 h. | J10: FARS 2020-2024 LA County (user's slide 8; FARS API blocked from sandbox) [S7]; Caltrans Mile Marker Sep 2015 major-incident clearance [S60]; Caltrans Traffic Ops Manual Ch.130 (2025) [S61]; Caltrans quick-clearance PI 2010 (secondary) [S8]; OTS LA County 2022/2023 rankings [S9]. | K10: lambda = fatal crashes/yr in LA County (952.5 avg 2020-24; ~2.6/day) x human share; these are excluded from rows 1 and 2, so the three tiers partition all incidents. Fatal crashes trigger multi-hour full closures for investigation and force diversion onto adjacent edges. Definitional caveat: many fatal crashes are on arterials and close 1 edge, not 3 - so this is an upper bound for '>=3 edges'. If you need strictly 3+ edges, use fatal crashes on freeways only: 210 fatal crashes on LA County state freeways in 2022 (Caltrans [S2]). Cross-check: TIMS/OTS report 868 traffic deaths in LA County in 2022. Hourly distribution from your FARS slide (peak 20-23 h ~7%/h) can modulate this rate. | L10: county-wide fatal crashes / yr | M10: x area factor (0.0831) | N10: =IF(ISNUMBER(H10),1-EXP(-H10),"n/a") -> 0.0085469046 | O10: FARS Data | P10: Empirical (Caltrans FY2014-15 major-incident mean) | Q10: =Assumptions!$C$37 -> 15 | R10: =IF(ISNUMBER(H10),H10/Q10,"n/a") -> 0.00057224259 | S10: 1
B11: 4 | C11: Traffic incident - AV | D11: edge | E11: low - reduced capacity | F11: =F6/Assumptions!$C$30*Assumptions!$C$9*Assumptions!$C$10 -> 16489.725 | G11: =F11/Assumptions!$C$7 -> 1.8823887 | H11: =G11*Assumptions!$C$6 -> 0.15642143 | I11: Same as row 1 (0.25-0.4 h; LA FSP 15.1 min on scene); no AV-specific clearance data. | J11: Waymo Safety Impact Hub, data through Mar 2026 [S10]; Kusano et al. 2025, Traffic Injury Prevention (56.7M RO miles; LA 6.4M) [S11]. | K11: lambda_AV = lambda_human(row 1) x AV VMT share (5%) x AV/human crash-rate ratio (police-reported any crash: 2.1/4.68 = 0.449). Replaces the earlier '0.449 x row 1' (which implicitly assumed 100% AV VMT). Ratio is all-locations; LA-specific ratios exist only for injury/airbag/serious outcomes. Row 1 is now multiplied by (1 - AV share) so total VMT is conserved; the AV formula divides that back out to the full-fleet base. Because row 1 now includes non-crash disablements, applying the CRASH ratio here assumes AV mechanical/stall incidents scale the same way (Assumption); AV-specific stalls are in row 7. Waymo LA exposure: 51.8M rider-only miles through Mar 2026. | L11: county-wide AV crashes / yr (5% AV VMT) | M11: x area factor (0.0831) | N11: =IF(ISNUMBER(H11),1-EXP(-H11),"n/a") -> 0.1448013 | O11: Derived | P11: Assumption (= row 1) | Q11: =Assumptions!$C$37 -> 15 | R11: =IF(ISNUMBER(H11),H11/Q11,"n/a") -> 0.010428096
B12: 5 | C12: Traffic incident - AV | D12: edge | E12: mid - no capacity | F12: =F9/Assumptions!$C$30*Assumptions!$C$9*Assumptions!$C$11 -> 43.33781 | G12: =F12/Assumptions!$C$7 -> 0.0049472386 | H12: =G12*Assumptions!$C$6 -> 0.00041110221 | I12: Same as row 2 (0.5-2 h, central ~1 h). | J12: Waymo Safety Impact Hub - Los Angeles any-injury 0.91 vs 2.42 IPMM; airbag 0.27 vs 1.19 [S10]; Kusano et al. 2025 [S11]. | K12: lambda_AV = lambda_human(row 2) x 5% x 0.376 (LA any-injury ratio, hub through Mar 2026, 51.8M LA miles). Replaces the 0.214 (0.6/2.80) ratio you flagged as not defensible. Alternative: LA airbag-deployment ratio 0.227. Caveat: injury-crash ratio is a proxy for lane-blocking-crash ratio; blockage caused by AV stalls (not crashes) is in row 7. | L12: county-wide AV SigAlert-class events / yr (5% AV VMT) | M12: x area factor (0.0831) | N12: =IF(ISNUMBER(H12),1-EXP(-H12),"n/a") -> 0.00041101772 | O12: Derived | P12: Assumption (= row 2) | Q12: =Assumptions!$C$38 -> 9 | R12: =IF(ISNUMBER(H12),H12/Q12,"n/a") -> 4.5678023e-05
B13: 6 | C13: Traffic incident - AV | D13: >=3 edges | E13: high - major closure / diversion | F13: =F10/Assumptions!$C$30*Assumptions!$C$9*Assumptions!$C$13 -> 7.14375 | G13: =F13/Assumptions!$C$7 -> 0.00081549658 | H13: =G13*Assumptions!$C$6 -> 6.776557e-05 | I13: Same as row 3 (3.3 h) - possibly longer because AV crashes attract extended investigation (NHTSA SGO reporting). | J13: Kusano et al. 2025 - LA serious injury+ -85% [39%, 99%] [S11]; Waymo Hub LA serious injury+: 0.00 vs 0.15 IPMM [S10]. | K13: lambda_AV = lambda_human(row 3) x 5% x 0.15. 0.15 is the conservative (upper) LA serious-injury ratio; the hub's all-locations ratio is 0.01/0.23 = 0.04 and LA shows zero events in 51.8M miles. Wide confidence interval - treat as order of magnitude. | L13: county-wide AV fatal-class events / yr (5% AV VMT) | M13: x area factor (0.0831) | N13: =IF(ISNUMBER(H13),1-EXP(-H13),"n/a") -> 6.7763274e-05 | O13: Derived | P13: Assumption (= row 3) | Q13: =Assumptions!$C$37 -> 15 | R13: =IF(ISNUMBER(H13),H13/Q13,"n/a") -> 4.5177047e-06 | S13: 1
B14: 7 | C14: Traffic incident - AV: remote operating center / connectivity down -> vehicle needs tow | D14: edge (many vehicles simultaneously) | E14: mid - stalled vehicles block lanes | F14: 1 | G14: =F14/Assumptions!$C$7 -> 0.00011415525 | H14: =G14*Assumptions!$C$6 -> 9.4859941e-06 | I14: Stalls: >= 2 min by definition; most self-resolve (96%); manual retrievals ~1-2 h (Cruise 28 Jun 2022: 'a couple of hours' until staff moved cars). Service suspension: ~6 h to next day (Waymo 20 Dec 2025). | J14: Waymo CPUC filing 30 Jan 2026 on the 20 Dec 2025 SF outage [S12]; TechCrunch on Cruise 28 Jun 2022 stall [S13]; LA Times / SF Standard on Cruise 11 Aug 2023 Outside Lands stalls [S14]; Cruise vehicle-retrieval events via SF Standard [S15]. | K14: SCENARIO ROW - no LA statistics exist. Documented fleet-wide stall events in SF: 28 Jun 2022 (Cruise, >6 vehicles, ~2 h, server issue); 11 Aug 2023 (Cruise, ~10 vehicles, cellular bandwidth); 20 Dec 2025 (Waymo, 829 vehicles in outage area, 1,593 stops >= 120 s in 11 h = 1.9 stops/vehicle, >96% resolved autonomously, <4% (~60) manual retrievals, 2 moved by first responders). That is ~3 events in 3.5 years for one city -> lambda ~ 1/yr placeholder (Assumption). Baseline (non-event) retrievals: Cruise logged 177 'vehicle retrieval events' Jan-Jul 2023 with a ~300-400 vehicle fleet -> ~0.8-1.0 retrievals per vehicle-year. Per event, assume 2-3% of the active fleet needs a tow (60/829 = 7% under extreme conditions; 6-10 vehicles of ~100-300 for Cruise). Correlate this row with power rows 9-12: the Dec 2025 stalls were caused by a grid outage darkening >7,000 signals. | L14: fleet-wide connectivity/remote-assist disruptions / yr (city scale) | M14: x area factor (0.0831) | N14: =IF(ISNUMBER(H14),1-EXP(-H14),"n/a") -> 9.4859491e-06 | O14: Assumption | P14: Empirical (sparse: 3 SF events) | Q14: =Assumptions!$C$37 -> 15 | R14: =IF(ISNUMBER(H14),H14/Q14,"n/a") -> 6.323996e-07
B15: 7b | C15: Traffic incident - AV: no battery (state-of-charge depletion) -> vehicle needs tow | D15: edge | E15: low - single vehicle stalled | F15: =0.04*F6/Assumptions!$C$30*Assumptions!$C$9 -> 1469.9412 | G15: =F15/Assumptions!$C$7 -> 0.16780151 | H15: =G15*Assumptions!$C$6 -> 0.013943854 | I15: Tow response: FSP average wait 7 min on LA freeways; AAA typical 30-60 min. Assume 0.5-1 h lane occupancy if stalled in lane. | J15: TIME / AAA 2023 EV roadside data [S16]; AAA 2024 (215,000 EV calls, 0.8% of events) [S17]; Metro FSP [S18]. | K15: GAP for a managed robotaxi fleet. Only consumer-EV data exist: AAA served 160,000 EVs in 2023 (0.5% of 32M roadside events); 4% of EV calls = ran out of charge -> ~6,400 out-of-charge events/yr nationally (~0.002 per EV-year assuming ~3M EVs). For a fleet with depot charging and SOC-aware dispatch this is better modeled as a CONSEQUENCE of depot failure (rows 9-12: depot dark -> vehicles below SOC threshold strand), not an independent hazard. Suggest: P(strand | depot outage > 4 h) x fleet share, or omit as an independent row. | L15: per vehicle-year (consumer EV proxy only) | M15: x area factor (0.0831) | N15: =IF(ISNUMBER(H15),1-EXP(-H15),"n/a") -> 0.013847088 | O15: GAP | P15: Empirical (FSP/AAA response times) | Q15: =Assumptions!$C$37 -> 15 | R15: =IF(ISNUMBER(H15),H15/Q15,"n/a") -> 0.00092959024
B16: 8 | C16: Traffic incident - AV: amplifier - obstruction of emergency response | D16: edge (conditional on emergency) | E16: amplifier - delays clearance of other hazards | F16: =55/(220/365) -> 91.25 | G16: =F16/Assumptions!$C$7 -> 0.010416667 | H16: =G16 -> 0.010416667 | I16: Obstruction 0.5-30 min; typical 'several minutes' (documented: 1 min, >2 min, >8 min, 30 min). Use +5 / +15 / +30 min added to the affected hazard's duration. | J16: Mission Local - 55 SFFD 'Autonomous Vehicle Incident' reports as of 8 Aug 2023 [S19]; SFMTA CPUC status conference 7 Aug 2023 (~600 reported AV incidents since launch; 'likely a fraction') [S20]; SF Standard fleet sizes (Cruise ~300 night/100 day, Waymo ~250) [S15]. | K16: Empirical but SF-specific and an undercount: 55 SFFD reports in 220 days (1 Jan-8 Aug 2023) = ~91/yr with ~550 driverless vehicles -> ~0.17 first-responder-interference incidents per vehicle-year. Scale to your fleet: lambda = 0.17 x (AV fleet size in model). Not area-scaled (fleet-based). Waymo's LA fleet is ~700-900 vehicles (2025-26), so LA-wide ~120-150/yr if SF rates hold; Waymo-only rates are likely lower than the 2023 Cruise-heavy mix. Model as a conditional multiplier on clearance time for rows 1-3, 9-10, 13-14 when an AV is present at the scene, not as an independent failure. | L16: incidents / yr per ~550-vehicle fleet (SF 2023) | M16: none (per-edge or per-fleet basis; see notes) | N16: =IF(ISNUMBER(H16),1-EXP(-H16),"n/a") -> 0.010362601 | O16: Empirical | P16: Empirical (SFFD report narratives) | Q16: n/a (system / regional / fleet event) | R16: =H16 -> 0.010416667
B17: 9 | C17: Power outage - unplanned (equipment, weather, third party), excluding major event days | D17: node | E17: low - depot dark | F17: =Assumptions!$C$19 -> 0.9037 | G17: =F17/Assumptions!$C$7 -> 0.0001031621 | H17: =G17 -> 0.0001031621 | I17: 1.8 h (CAIDI 107 min, 10-yr avg 2016-2025; 2024: 111 min; 2025: 121 min). | J17: SCE 2025 Annual Electric Reliability Report, Tables 1 & 3 (SAIFI/CAIDI unplanned, MED excluded) [S21]; SCE 2024 report [S22]. | K17: Per-customer index -> already a per-node rate; no area scaling. SAIFI excl. MED: 0.90/customer-yr (10-yr avg 2016-2025 = 0.904); 2023 0.937, 2024 0.901, 2025 0.963. Your draft used 1.4 (= 2025 SAIFI INCLUDING MEDs) - that double-counts row 10. District values for LA County SCE districts (Table 6 of the report) range roughly 0.5-1.5; use them if node locations are fixed. System-level rate for 10 independent nodes = 10 x 0.90 = 9.0 depot outages/yr. Note LADWP serves the City of LA (different reliability; not covered here) - GAP if any node is inside LADWP territory. | L17: interruptions per customer-year (per node) | M17: none (per-node index); system = x10 nodes | N17: =IF(ISNUMBER(H17),1-EXP(-H17),"n/a") -> 0.00010315678 | O17: Empirical | P17: Empirical (SCE CAIDI excl. MED) | Q17: per node (x1) | R17: =H17 -> 0.0001031621
B18: 10 | C18: Power outage - major event day (storms, windstorm-PSPS combinations, substation loss) | D18: node (often multi-node) | E18: mid - depot dark for many hours | F18: =Assumptions!$C$21-Assumptions!$C$19 -> 0.1834 | G18: =F18/Assumptions!$C$7 -> 2.0936073e-05 | H18: =G18 -> 2.0936073e-05 | I18: 8.6 h mean (MED-attributable CAIDI = MED SAIDI / MED SAIFI = 94.8 min / 0.183 = 517 min, 10-yr avg 2016-2025); 2023: 202 min; 2024: 652 min; 2025: 1,004 min. Heavy tail: on 7 Jan 2025, 52% of 731k affected customers were out < 1 h but 19% > 1 day and 2.5% >= 7 days. | J18: SCE 2025 Annual Electric Reliability Report Tables 1, 2, 17 [S21]; SCE 2024 report Table 2 (5 MEDs, 4 PSPS-driven) [S22]. | K18: MED-attributable per-customer rate = SAIFI(incl. MED) - SAIFI(excl. MED) = 1.088 - 0.904 = 0.18 interruptions/customer-yr (10-yr avg of Table 3; SCE Table 1 rounding gives 1.09 - 0.90 = 0.19). Year-to-year: 2023 0.099; 2024 0.089; 2025 0.427 (21 MEDs, 15 in January 2025 windstorm/fires). Your draft's lambda = 6 was the COUNT of MED days (2023), not a per-node rate - MED days are system-wide days, most of which do not touch any given customer. MED outages are spatially correlated: model as a system event with rate ~5-21 MED days/yr and P(node affected | MED) ~ 0.18/(MED days) ~ 1-4%. PSPS days are counted here when they exceed the MED threshold (T_MED = 2.04 min daily SAIDI in 2025), so avoid double counting with row 12. | L18: MED-attributable interruptions per customer-year (per node) | M18: none (per-node index); system = x10 nodes | N18: =IF(ISNUMBER(H18),1-EXP(-H18),"n/a") -> 2.0935854e-05 | O18: Derived | P18: Derived (SCE SAIDI/SAIFI differences; Table 17 distribution) | Q18: per node (x1) | R18: =H18 -> 2.0936073e-05 | S18: 1
B19: 11 | C19: Power outage - planned maintenance | D19: node | E19: planned - depot dark, schedulable | F19: =Assumptions!$C$24 -> 0.31133333 | G19: =F19/Assumptions!$C$7 -> 3.5540335e-05 | H19: =G19 -> 3.5540335e-05 | I19: 5.0 h mean (planned CAIDI: 2023 330 min; 2024 247 min; 2025 323 min). Customers notified in advance. | J19: SCE 2025 Annual Electric Reliability Report Table 7 (planned + unplanned) minus Table 3 (unplanned) [S21]. | K19: Derived from SCE's own indices: planned SAIFI = 0.31/customer-yr (avg 2023-25: 0.332, 0.349, 0.253); planned SAIDI ~82-110 min/yr. Replaces the qmerit blog value (1/yr). SCE notes 2022-2025 planned indices use a new meter-data method and are not comparable with earlier years. Planned outages are announced and typically daytime weekday - consider scheduling them deterministically rather than as Poisson arrivals. | L19: planned interruptions per customer-year (per node) | M19: none (per-node index); system = x10 nodes | N19: =IF(ISNUMBER(H19),1-EXP(-H19),"n/a") -> 3.5539703e-05 | O19: Derived | P19: Derived (planned SAIDI / planned SAIFI) | Q19: per node (x1) | R19: =H19 -> 3.5540335e-05
B20: 12 | C20: Power outage - PSPS (public safety power shutoff) | D20: >=3 nodes | E20: high - multiple depots dark >= 1 day | F20: =Assumptions!$C$26 -> 5 | G20: =F20/Assumptions!$C$7 -> 0.00057077626 | H20: =IF(ISNUMBER(Assumptions!$C$27),G20*Assumptions!$C$27,"needs q") -> needs q | I20: 24-48 h typical; restoration <= 6-8 h after the weather 'period of concern' ends (SCE); Jan 2025 events lasted several days for some circuits. | J20: SCE 2026 PSPS Action Plan (events/yr: 12 in 2020, 8 in 2023, 20 in 2024, 14 in 2025; restoration intervals) [S23]; CPUC PSPS post-event reports 2024 (LA County events) [S24]; SCE 2025 reliability report Table 17 (Jan 2025 duration distribution) [S21]. | K20: lambda = PSPS de-energization events touching LA County ~5/yr (2024 count; SCE system-wide 8-20/yr). G = lambda/8760 x q where q = P(>=3 of your 10 nodes are on de-energized circuits | event). q is a GAP: only HFRA circuits (foothills, Santa Clarita, Malibu, Antelope Valley edges) are PSPS-eligible; urban basin depots have q ~ 0. Look each node up on SCE's PSPS circuit map. Oct 2024 event de-energized 11,381 LA County customers; Jan 7-9 2025 event affected ~731k SCE customers (weather + PSPS) - the tail case. Do not also count these days in row 10. | L20: PSPS events touching LA County / yr x q | M20: x q (P(>=3 nodes | PSPS event)) - GAP | N20: =IF(ISNUMBER(H20),1-EXP(-H20),"n/a") -> n/a | O20: Empirical (rate) / GAP (q) | P20: Empirical (SCE action plan; Table 17) | Q20: n/a (system / regional / fleet event) | R20: =H20 -> needs q
B21: 13 | C21: Wildfire - >= 1 edge closed >= 24 h | D21: edge | E21: mid - edge closed for days to months | F21: =8/6 -> 1.3333333 | G21: =F21/Assumptions!$C$7 -> 0.000152207 | H21: =G21*Assumptions!$C$6 -> 1.2647992e-05 | I21: 1 day to 4+ months; median ~1-2 weeks. Examples: Route Fire 2022 I-5 full closure ~1 day then lane closures ~2 weeks; Bridge Fire 2024 SR-39/SR-2 weeks; Palisades 2025 PCH closed 7 Jan-23 May 2025 (~4.5 months; partial Feb). | J21: CAL FIRE incident archives 2020-2025, LA County entries [S25]; Caltrans D7 Route Fire releases [S26]; AP/ABC7 Hughes Fire I-5 closure [S27]; Fox Weather / Governor's office PCH reopening [S28]; LA Times Bobcat Fire SR-2 closure [S29]; Caltrans emergency road closures dataset (user's source) [S30]. | K21: Derived count of LA County fires that closed a state highway or major arterial >= 24 h, 2020-2025: Bobcat 2020 (SR-2, SR-39, weeks), Lake 2020 (Lake Hughes Rd), Route 2022 (I-5), Bridge 2024 (SR-39/SR-2), Franklin 2024 (PCH, days), Palisades 2025 (PCH, months), Eaton 2025 (Altadena arterials, weeks), Hughes 2025 excluded (I-5 closed only hours) -> ~8 in 6 yr = 1.3/yr. Upper bound: LA County fires >= 1,000 acres 2020-25 = 13 (2.2/yr); >= 300 acres ~27 (4.5/yr). CAL FIRE pages omit some federal-responsibility fires (e.g., Bobcat), so counts are floors. Exposure caveat: fire-closure risk is concentrated on WUI/mountain edges (SR-2, SR-39, I-5 Newhall/Castaic, PCH, SR-14); an urban-basin edge has near-zero burn probability. Use FRAP burn-probability rasters per edge instead of uniform area scaling if edges are fixed. | L21: county-wide qualifying fires / yr (2020-2025) | M21: x area factor (0.0831) | N21: =IF(ISNUMBER(H21),1-EXP(-H21),"n/a") -> 1.2647912e-05 | O21: Derived | P21: Empirical (news/Caltrans closure records) | Q21: =Assumptions!$C$42 -> 4 | R21: =IF(ISNUMBER(H21),H21/Q21,"n/a") -> 3.161998e-06 | S21: 1
B22: 14 | C22: Wildfire - >= 3 edges closed simultaneously (Palisades / Saddleridge level) | D22: >=3 edges | E22: high - regional diversion, evacuation traffic | F22: =5/26 -> 0.19230769 | G22: =F22/Assumptions!$C$7 -> 2.1952933e-05 | H22: =G22*Assumptions!$C$6 -> 1.8242296e-06 | I22: Freeway closures: hours to ~1-2 days (Saddleridge 2019: I-5, SR-14, I-210 closed overnight; most reopened next day). Arterials/PCH: weeks to months. Evacuation surge: ~1-3 days. | J22: LA Times 11 Oct 2019 Saddleridge freeway closures [S31]; CAL FIRE top-20 destructive fires (user's source) [S32]; CAL FIRE 2025 incidents (Palisades, Eaton, Hughes) [S25]; Zehra & Wong 2024 systematic review (81 CA highway-damaging fires 2015-2020) [S33]. | K22: Derived: county-level fire events since 2000 that closed >= 3 major highway edges at once: Oct 2007 (Buckweed/Ranch/Magic: I-5, SR-14, SR-126 - NOT re-verified here), Sayre 2008 (I-5/SR-14/SR-210), Woolsey 2018 (US-101, PCH, canyon roads), Saddleridge 2019 (I-5, SR-14, I-210, SR-118 connectors - verified), Palisades/Eaton Jan 2025 -> ~5 in 26 yr = 0.19/yr (range 0.1-0.3). Your draft's 0.6/yr from the top-20 destructive list is not reproducible: that list has 6 LA County entries over 1961-2025 (~0.09/yr). These events coincide with Santa Ana wind days (Oct-Jan) and with PSPS (row 12) and MED (row 10) - model as a common-cause 'wind event' rather than independent hazards. | L22: county-wide multi-edge fire events / yr (2000-2025) | M22: x area factor (0.0831) | N22: =IF(ISNUMBER(H22),1-EXP(-H22),"n/a") -> 1.824228e-06 | O22: Derived | P22: Empirical (news closure records) | Q22: n/a (system / regional / fleet event) | R22: =H22 -> 1.8242296e-06
B23: 15 | C23: Flood - edge in 100-yr floodplain impassable | D23: edge | E23: mid - edge closed | F23: =0.01-0.002 -> 0.008 | G23: =F23/Assumptions!$C$7 -> 9.1324201e-07 | H23: =G23 -> 9.1324201e-07 | I23: Hours to 1-2 days (flash-flood / debris on roadway); longer if pavement or bridge damaged. | J23: FEMA IS-0273 / flood-zone AEP definitions (user's footnotes) [S34]; Caltrans District 7 emergency closures (user's source) [S30]. | K23: Kept your logic: P(edge inundated) = 1% - 0.2% = 0.8%/yr applies ONLY to edges inside the 1%-AEP SFHA (Zone A/AE/AO), not to all edges - so 'after scaling' should be x (number of edges in SFHA), not x area ratio. GAP: an empirical LA County count of weather-related road closures per year was not obtained (NCEI Storm Events database 'Flash Flood' events for LA County, or Caltrans LCS emergency-closure history, would give it). Note LA's engineered channels mean most urban flooding is local ponding (hours), not floodplain inundation. | L23: per SFHA edge-year | M23: none (per-edge or per-fleet basis; see notes) | N23: =IF(ISNUMBER(H23),1-EXP(-H23),"n/a") -> 9.1324159e-07 | O23: PEMS Def | P23: Assumption | Q23: =Assumptions!$C$40 -> 1 | R23: =H23 -> 9.1324201e-07
B24: 16 | C24: Flood - 500-yr regional event, >= 3 edges impassable | D24: >=3 edges | E24: high | F24: 0.002 | G24: =F24/Assumptions!$C$7 -> 2.283105e-07 | H24: =G24 -> 2.283105e-07 | I24: 1-3 days (regional storm; e.g., Feb 2024 atmospheric river closed multiple LA canyon roads and I-5 Grapevine for ~1 day). | J24: FEMA 0.2%-AEP definition (user's footnote) [S34]. | K24: Kept your value. 0.2%/yr is the exceedance probability for the 500-yr flood at a point; the probability that >= 3 specific edges are simultaneously closed is a joint event that needs edge-level flood-zone exposure. GAP: no LA County-specific multi-road flood closure frequency found; suggest NCEI Storm Events (LA County, 'Flood' + 'Flash Flood' events 2000-2025) as the empirical base. | L24: per region-year (500-yr AEP) | M24: none (per-edge or per-fleet basis; see notes) | N24: =IF(ISNUMBER(H24),1-EXP(-H24),"n/a") -> 2.2831048e-07 | O24: PEMS Def | P24: Assumption | Q24: n/a (system / regional / fleet event) | R24: =H24 -> 2.283105e-07
B25: 18 | C25: Earthquake M >= 6.7, LA region - >= 3 edges damaged | D25: >=3 edges | E25: high - weeks to months | F25: =Assumptions!$C$29 -> 0.030543024 | G25: =F25/Assumptions!$C$7 -> 3.4866466e-06 | H25: =G25 -> 3.4866466e-06 | I25: Weeks to months for damaged freeways: Northridge 1994 I-10 closed 17 Jan-12 Apr 1994 (84 days; 66-day reconstruction); I-5/SR-14 interchange rebuilt over months; SR-118 and I-5 Gavin Canyon bridges also collapsed. | J25: USGS UCERF3 FAQ (60% in 30 yr for M >= 6.7, LA region) [S39]; Northridge transportation study (ROSAP DOT-521) [S40]; Wikipedia / EScholarship Northridge economic impacts (freeway closures) [S41]. | K25: lambda = -ln(1-0.60)/30 = 0.0305/yr is REGIONAL (whole LA region), not per model area, so no area scaling. P(>= 3 edges damaged | M >= 6.7) depends on epicentre distance and bridge fragility: Northridge (M6.7) damaged 4 major freeways within ~30 km. For a 10-node network spanning 337 sq mi, treating P(>= 3 edges | event) ~ 0.5-1.0 is defensible only if the network is near the rupture; otherwise use HAZUS bridge fragility per edge. Aftershock-driven re-closures and inspection closures (hours-days) affect all edges immediately after the event even without damage. | L25: regional events / yr (M >= 6.7) | M25: none (regional rate; all nodes exposed) | N25: =IF(ISNUMBER(H25),1-EXP(-H25),"n/a") -> 3.4866405e-06 | O25: Empirical (rate) / Assumption (P(>=3 edges)) | P25: Empirical (Northridge 1994) | Q25: n/a (system / regional / fleet event) | R25: =H25 -> 3.4866466e-06 | S25: 1
B27: AV-share sensitivity: change Assumptions!C9 (AV share of VMT). Cells that move: F6 (row 1), F9 (row 2), F10 (row 3) via C30 = 1 - C9; F11, F12, F13 (rows 4-6) directly; and every G, H, N, R in those six rows. Nothing else depends on C9.

Sheet Assumptions
B2: Model parameters and shared inputs (edit here; the table recalculates)
B3: Parameter | C3: Value | D3: Unit | E3: Source / note
B4: LA County land area (sq mi) | C4: 4060.3 | D4: sq mi | E4: Meeting slides (slide 4); consistent with US Census county area.
B5: Model region area (10 nodes) (sq mi) | C5: 337.4 | D5: sq mi | E5: Meeting slides: 10 nodes of 120.35 depots at 5% AV demand -> 337.4 sq mi.
B6: Area scaling factor (model / county) | C6: =C5/C4 -> 0.083097308 | D6: ratio | E6: Equals 337.4 / 4060.3 = 0.0831. Applied to county-wide, area-distributed hazards (traffic, AV, fire, flood, debris flow). NOT applied to per-customer power indices (already per node) or to regional earthquake rate.
B7: Hours per year | C7: 8760 | D7: h | E7: Non-leap year.
B8: Number of nodes (depots) in model | C8: 10 | D8: nodes | E8: Meeting slides.
B9: AV share of VMT in model | C9: 0.05 | D9: fraction | E9: Meeting slides: 5% AV demand. Used to split human vs AV traffic hazards.
B10: AV/human ratio: police-reported (any) crash rate | C10: =2.1/4.68 -> 0.44871795 | D10: ratio | E10: Kusano et al. 2025 / user footnote (PubMed 39485678): 2.1 vs 4.68 police-reported crashes per M miles, all locations. Used for LOW severity (row 4).
B11: AV/human ratio: any-injury crash rate, Los Angeles | C11: =0.91/2.42 -> 0.37603306 | D11: ratio | E11: Waymo Safety Impact Hub (data through Mar 2026), LA: 0.91 vs 2.42 IPMM (-62%). Used for MID severity (row 5).
B12: AV/human ratio: airbag-deployment crash rate, Los Angeles | C12: =0.27/1.19 -> 0.22689076 | D12: ratio | E12: Waymo Safety Impact Hub, LA: 0.27 vs 1.19 IPMM (-77%). Alternative for row 5.
B13: AV/human ratio: serious-injury-or-worse crash rate | C13: 0.15 | D13: ratio | E13: Kusano et al. 2025 (TIP), LA serious injury+: -85% [39%, 99%] -> 0.15. Hub LA shows 0.00 vs 0.15 (0 events in 51.8M mi); all-locations 0.01/0.23 = 0.04. 0.15 used as conservative value (row 6).
B14: PDO share of police-reported crashes (state highways, LA County 2022) | C14: =26429/39689 -> 0.66590239 | D14: fraction | E14: Caltrans 2022 Crash Data on California State Highways, LA County: 26,429 PDO of 39,689 crashes. Used to gross up TIMS fatal+injury counts to all-severity.
B15: LA County fatal+injury crashes per year (TIMS/SWITRS, 2022) | C15: 40449 | D15: crashes/yr | E15: TIMS (UC Berkeley SafeTREC) county total for 2022 as reported by secondary sources (mylawcompany.com; arashlaw.com gives 40,717 for 2023 and 40,389 for 2024). PRIMARY TIMS EXPORT NOT VERIFIED (login required) - flag.
B16: LA County state-highway crashes, all severities (Caltrans 2022) | C16: 39689 | D16: crashes/yr | E16: Caltrans 2022 Crash Data on California State Highways, LA County total (831.7 route-miles, 37,516.6 MVM; 26,429 PDO / 13,006 injury / 254 fatal).
B17: LA County SigAlerts per year (2018) | C17: 2515 | D17: events/yr | E17: CHP data via Crosstown LA: 2,515 SigAlerts in 2018 on 11 LA County freeways (2,239 in 2016). SigAlert = >=1 lane blocked >=30 min.
B18: LA County fatal crashes per year (FARS 2020-2024 avg) | C18: 952.5 | D18: crashes/yr | E18: User's slide 8 (FARS query). Could not re-run FARS API from sandbox (HTTP 403). Cross-check: TIMS/OTS report 868 traffic deaths in LA County in 2022 - same order of magnitude.
B19: SCE SAIFI, unplanned, MED excluded (10-yr avg 2016-2025) | C19: =Working!G16 -> 0.9037 | D19: interruptions/customer-yr | E19: Average of SCE 2025 Annual Electric Reliability Report Table 3 (Working sheet); SCE Table 1 rounds to 0.90. 2023: 0.937; 2024: 0.901; 2025: 0.963.
B20: SCE CAIDI, unplanned, MED excluded (10-yr avg 2016-2025) (min) | C20: =Working!H16 -> 107.321 | D20: min | E20: Average of Table 3 (Working sheet); SCE Table 1 gives 107.32. 2023: 102.31; 2024: 111.25; 2025: 120.79.
B21: SCE SAIFI, unplanned, MED included (10-yr avg 2016-2025) | C21: =Working!D16 -> 1.0871 | D21: interruptions/customer-yr | E21: SCE 2025 report Table 1.
B22: SCE SAIDI, unplanned, MED included (10-yr avg) (min) | C22: =Working!C16 -> 192.045 | D22: min | E22: SCE 2025 report Table 1.
B23: SCE SAIDI, unplanned, MED excluded (10-yr avg) (min) | C23: =Working!F16 -> 97.243 | D23: min | E23: SCE 2025 report Table 1.
B24: SCE planned-outage SAIFI (avg 2023-2025) | C24: =AVERAGE(1.269-0.937,1.25-0.901,1.216-0.963) -> 0.31133333 | D24: interruptions/customer-yr | E24: Derived: (planned+unplanned SAIFI, MED excl., Table 7) minus (unplanned SAIFI, MED excl., Table 3), SCE 2025 report. 2023: 0.332; 2024: 0.349; 2025: 0.253.
B25: SCE planned-outage CAIDI (avg 2023-2025) (min) | C25: =AVERAGE((205.6-95.86)/(1.269-0.937),(186.33-100.25)/(1.25-0.901),(198.18-116.37)/(1.216-0.963)) -> 300.18314 | D25: min | E25: Derived: planned SAIDI / planned SAIFI by year (2023: 330 min; 2024: 247 min; 2025: 323 min).
B26: SCE PSPS events touching LA County per year (2024) | C26: 5 | D26: events/yr | E26: CPUC PSPS post-event reports 2024 involving LA County (Jun, Aug, Sep, Oct, Dec). System-wide SCE PSPS events: 12 (2020), 8 (2023), 20 (2024), 14 (2025) per SCE 2026 PSPS Action Plan.
B27: q = P(>=3 of 10 nodes de-energized | PSPS event) | D27: probability | E27: GAP - depends on whether depot nodes sit on PSPS-eligible (HFRA) circuits. Urban LA basin circuits are mostly not PSPS-eligible; foothill/Santa Clarita/Malibu circuits are. Needs SCE circuit map lookup per node.
B28: USGS 30-yr probability of M>=6.7 in LA region (UCERF3) | C28: 0.6 | D28: probability | E28: USGS FAQ (UCERF3): 60% in 30 years (M7: 46%; M7.5: 31%).
B29: Annual rate of M>=6.7, LA region | C29: =-LN(1-C28)/30 -> 0.030543024 | D29: events/yr | E29: Poisson conversion: lambda = -ln(1-P)/T = 0.0305/yr.
B30: Human-driver share of VMT (= 1 - AV share) | C30: =1-C9 -> 0.95 | D30: fraction | E30: Total VMT is held fixed: AVs replace human VMT. Rows 1-3 are multiplied by this; rows 4-6 by C9. CHANGE C9 ONLY.
B31: Collision share of freeway incidents (LA FSP assists, FY2020-21) | C31: 0.164 | D31: fraction | E31: UPDATED: Mauch & Skabardonis 2022, California FSP MIS Annual Report FY2020-21, Los Angeles: 38,887 collision assists of 237,752 (16.4%); mechanical 14.0%, flat tire 16.5%, out of gas 6.5%, debris 2.0%, abandoned 2.4%, overheated 4.7%, other 37.5%. Replaces Giuliano 1989 (11% accidents of CHP-logged incidents, I-10, 1983-85), now kept as a lower-bound cross-check. Caveat: FSP covers patrolled freeway beats in service hours only.
B32: Share of incidents with vehicle in a travel lane (LA FSP, FY2020-21) | C32: 0.103 | D32: fraction | E32: UPDATED: Mauch & Skabardonis 2022, LA: 24,411 of 237,752 assists in lane (10.3%); right shoulder 77.4%, left shoulder 2.3%. Replaces Giuliano 1989 (18% closed >= 1 lane). Range 0.05-0.18 (I-880 1995: 4-5%; Giuliano: 18%).
B33: Rain days per year, downtown LA (>= 0.01 in) | C33: 34.1 | D33: days/yr | E33: NOAA 1991-2020 normals for Los Angeles (Downtown/USC) as tabulated on Wikipedia 'Climate of Los Angeles'; weather.com gives 36. Row 1b.
B34: LA County daily VMT, all public roads, 2022 (thousand veh-mi/day) | C34: 195997.4 | D34: thousand mi/day | E34: OTS Crash Rankings, Los Angeles County 2022 (DVMT field; Caltrans HPMS origin).
B35: LA County freeway annual VMT, 2022 (million veh-mi) | C35: 35488.3 | D35: MVM/yr | E35: Caltrans 2022 Crash Data on CA State Highways, LA County freeway segment travel.
B36: Freeway share of LA County VMT | C36: =C35/(C34*365/1000) -> 0.49606892 | D36: fraction | E36: Equals 35,488 / 71,539 MVM = 0.50. Consistent with Tracking California ('nearly half of all VMT on Interstates, freeways and expressways'). Used to justify the freeway/arterial edge split.
B37: Number of edges in model network (ASSUMPTION) | C37: 15 | D37: edges | E37: 10 nodes, average degree 3 -> 15 edges. Planar bounds: tree 9 edges (=C8-1), maximal planar 24 (=3*C8-6). Justification: US urbanized-area street networks average 2.76 streets per node (Boeing 2020, 497 urbanized areas); a depot-level abstraction with degree ~3 is consistent. Override with your actual topology.
B38: Freeway-dominated edges (ASSUMPTION) | C38: 9 | D38: edges | E38: 60% of edges. Freeways carry ~50% of county VMT (C36) but inter-depot trips (~5-10 mi in a 337 sq mi region) are longer than the average trip and freeway-weighted, so a >50% share is assumed. Range 7-11.
B39: Arterial-dominated edges | C39: =C37-C38 -> 6 | D39: edges | E39: Remainder.
B40: Edges crossing the 1%-AEP (100-yr) SFHA (ASSUMPTION) | C40: 1 | D40: edges | E40: Only 4.19 sq mi (0.09%) of LA County is mapped 1%-AEP SFHA (LA County All-Hazards Mitigation Plan 2020) because channels are engineered; but SFHAs are linear (LA / San Gabriel / Rio Hondo river corridors) so a route network of ~90 edge-miles plausibly crosses one. Range 0-2.
B41: Edges in the 0.2%-AEP (500-yr) zone (ASSUMPTION) | C41: 3 | D41: edges | E41: 243.32 sq mi (5.11%) of the county is in the 0.2%-AEP zone (same plan); 5% of 15 edges by area would be <1, but the zone follows the same river/valley corridors that the freeways follow (I-710, I-605, I-5 along the rivers). Range 2-4.
...

Sheet Working
B2: Intermediate data behind the table
B4: SCE system reliability indices, unplanned outages (SCE 2025 Annual Electric Reliability Report, Table 3; planned+unplanned from Table 7)
B5: Year | C5: SAIDI incl MED | D5: SAIFI incl MED | E5: CAIDI incl MED | F5: SAIDI excl MED | G5: SAIFI excl MED | H5: CAIDI excl MED | I5: P+U SAIDI excl MED | J5: P+U SAIFI excl MED | K5: MED days | L5: MED SAIFI (=C-F) | M5: MED CAIDI min (=(B-E)/K) | N5: Planned SAIFI (=I-F) | O5: Planned CAIDI min (=(H-E)/M)
B6: 2016 | C6: 134.48 | D6: 1.1 | E6: 122.26 | F6: 109.98 | G6: 0.994 | H6: 110.69 | L6: =D6-G6 -> 0.106 | M6: =(C6-F6)/L6 -> 231.13208
B7: 2017 | C7: 139.73 | D7: 1.192 | E7: 117.19 | F7: 91.72 | G7: 0.87 | H7: 105.4 | L7: =D7-G7 -> 0.322 | M7: =(C7-F7)/L7 -> 149.09938
B8: 2018 | C8: 136.82 | D8: 0.874 | E8: 156.61 | F8: 71.25 | G8: 0.716 | H8: 99.58 | L8: =D8-G8 -> 0.158 | M8: =(C8-F8)/L8 -> 415
B9: 2019 | C9: 177.97 | D9: 1.04 | E9: 171.17 | F9: 90.75 | G9: 0.866 | H9: 104.75 | L9: =D9-G9 -> 0.174 | M9: =(C9-F9)/L9 -> 501.26437
B10: 2020 | C10: 201.32 | D10: 1.057 | E10: 190.47 | F10: 91.4 | G10: 0.866 | H10: 105.51 | I10: 218.59 | J10: 1.195 | L10: =D10-G10 -> 0.191 | M10: =(C10-F10)/L10 -> 575.49738 | N10: =J10-G10 -> 0.329 | O10: =(I10-F10)/N10 -> 386.59574
B11: 2021 | C11: 179.79 | D11: 1.112 | E11: 161.7 | F11: 103.82 | G11: 0.96 | H11: 108.1 | I11: 319.91 | J11: 1.397 | L11: =D11-G11 -> 0.152 | M11: =(C11-F11)/L11 -> 499.80263 | N11: =J11-G11 -> 0.437 | O11: =(I11-F11)/N11 -> 494.48513
B12: 2022 | C12: 131.13 | D12: 1.08 | E12: 121.45 | F12: 101.03 | G12: 0.964 | H12: 104.83 | I12: 205.83 | J12: 1.285 | L12: =D12-G12 -> 0.116 | M12: =(C12-F12)/L12 -> 259.48276 | N12: =J12-G12 -> 0.321 | O12: =(I12-F12)/N12 -> 326.47975
B13: 2023 | C13: 115.9 | D13: 1.036 | E13: 111.93 | F13: 95.86 | G13: 0.937 | H13: 102.31 | I13: 205.6 | J13: 1.269 | K13: 6 | L13: =D13-G13 -> 0.099 | M13: =(C13-F13)/L13 -> 202.42424 | N13: =J13-G13 -> 0.332 | O13: =(I13-F13)/N13 -> 330.54217
B14: 2024 | C14: 158.3 | D14: 0.99 | E14: 159.96 | F14: 100.25 | G14: 0.901 | H14: 111.25 | I14: 186.33 | J14: 1.25 | K14: 5 | L14: =D14-G14 -> 0.089 | M14: =(C14-F14)/L14 -> 652.24719 | N14: =J14-G14 -> 0.349 | O14: =(I14-F14)/N14 -> 246.64756
B15: 2025 | C15: 545.01 | D15: 1.39 | E15: 392.1 | F15: 116.37 | G15: 0.963 | H15: 120.79 | I15: 198.18 | J15: 1.216 | K15: 21 | L15: =D15-G15 -> 0.427 | M15: =(C15-F15)/L15 -> 1003.8407 | N15: =J15-G15 -> 0.253 | O15: =(I15-F15)/N15 -> 323.35968
B16: 10-yr avg | C16: =AVERAGE(C6:C15) -> 192.045 | D16: =AVERAGE(D6:D15) -> 1.0871 | E16: =AVERAGE(E6:E15) -> 170.484 | F16: =AVERAGE(F6:F15) -> 97.243 | G16: =AVERAGE(G6:G15) -> 0.9037 | H16: =AVERAGE(H6:H15) -> 107.321 | L16: =D16-G16 -> 0.1834 | M16: =(C16-F16)/L16 -> 516.91385
B17: Note: 2020-2021 planned indices are SCE 'conservative interim estimates'; 2022-2025 use the new meter-data method (not comparable with earlier years). MED threshold T_MED = 2.07 min (2024), 2.04 min (2025) daily SAIDI.
B19: Customers by outage duration, 7 Jan 2025 MED (Metro East; weather + PSPS) - SCE 2025 report Table 17
B20: 0-1 h | C20: 1-5 h | D20: 5-10 h | E20: 10-15 h | F20: 15-20 h | G20: 20-24 h | H20: 1-2 d | I20: 2-3 d | J20: 3-4 d | K20: 4-5 d | L20: 5-6 d | M20: 6-7 d | N20: >=7 d | O20: Total
B21: 380461 | C21: 131697 | D21: 22453 | E21: 12848 | F21: 23835 | G21: 12966 | H21: 51329 | I21: 62121 | J21: 13782 | K21: 942 | L21: 53 | M21: 734 | N21: 17951 | O21: 731172
B22: =B21/$O$21 -> 0.52034405 | C22: =C21/$O$21 -> 0.18011767 | D22: =D21/$O$21 -> 0.030708233 | E22: =E21/$O$21 -> 0.017571789 | F22: =F21/$O$21 -> 0.032598349 | G22: =G21/$O$21 -> 0.017733174 | H22: =H21/$O$21 -> 0.070200992 | I22: =I21/$O$21 -> 0.084960857 | ... N22: =N21/$O$21 -> 0.024550995 | O22: share
B24: Caltrans 2022 Crash Data on California State Highways - Los Angeles County totals
B25: Segment | C25: Road miles | D25: Travel (MVM) | E25: Crashes total | F25: PDO | G25: Injury | H25: Fatal | I25: Killed | J25: Injured | K25: Crashes / MVM (=E/D) | L25: Crashes / route-mile-yr (=E/C)
B26: Freeway (countywide) | C26: 537 | D26: 35488.3 | E26: 37707 | F26: 25428 | G26: 12069 | H26: 210 | I26: 220 | J26: 17502 | K26: =E26/D26 -> 1.0625192 | L26: =E26/C26 -> 70.217877
B27: Non-freeway state hwy | C27: 294.6 | D27: 2028.3 | E27: 1982 | F27: 1001 | G27: 937 | H27: 44 | I27: 47 | J27: 1415 | K27: =E27/D27 -> 0.977173 | L27: =E27/C27 -> 6.7277665
B28: All state highways, LA County | C28: 831.7 | D28: 37516.6 | E28: 39689 | F28: 26429 | G28: 13006 | H28: 254 | I28: 267 | J28: 18917 | K28: =E28/D28 -> 1.057905 | L28: =E28/C28 -> 47.720332
B29: Statewide (reference) | C29: 15001.5 | D29: 182117.3 | E29: 147704 | F29: 95171 | G29: 50904 | H29: 1629 | I29: 1772 | J29: 73827 | K29: =E29/D29 -> 0.81103772 | L29: =E29/C29 -> 9.8459487
B31: Giuliano (1989) I-10 incident characteristics (12-mile section, ADT 250-275k, 1983-85)
B32: Reported incidents per day (CHP logs, 22 days) | C32: 29.6
B33: Share accidents / disablements / other | C33: 11% / 80% / 9%
B34: Accidents per weekday / weekend day | C34: 3.1 / 2.2
B35: Share of incidents closing >=1 lane | C35: 0.18
B36: Share of incidents closing >=2 lanes | C36: 0.02
B37: Accidents: 0 / 1 / 2 / >=3 lanes closed | C37: 59% / 28% / 8% / 5%
B38: Mean duration, all incidents (min) | C38: 37
B39: SD duration (min) | C39: 30
B40: Share cleared <= 1 h / > 2 h | C40: 82% / 2%
B41: Injury accident, lanes closed, day / night (min) | C41: 54 / 66
B42: Disablement, lanes closed (min) | C42: 14-18
B43: Lane-blocking incidents > 2 h, share of all incidents | C43: 0.006
B45: CAL FIRE incident archive - Los Angeles County entries (counts by size; pages omit some federal fires, e.g. Bobcat 2020)
B46: Year | C46: Listed LA County incidents | D46: >= 300 acres | E46: >= 1,000 acres | F46: >= 10,000 acres | G46: Closed a major road >= 24 h (judgement) | H46: Named fires
...

Sheet Sources
B2: Sources (IDs referenced in the table)
B3: ID | C3: Source | D3: URL | E3: Used for | F3: Access / verification note
B4: S1 | C4: Giuliano, G. (1989). Incident characteristics, frequency, and duration on a high volume urban freeway. Transportation Research A 23(5). UC Irvine ITS working paper. | D4: https://escholarship.org/content/qt59m3d34v/qt59m3d34v.pdf | E4: Secondary / lower-bound cross-check for rows 1-2 (replaced by S58 in v4) | F4: Full text read.
B5: S2 | C5: Caltrans (2024). 2022 Crash Data on California State Highways - County summary for Los Angeles County. | D5: https://dot.ca.gov/-/media/dot-media/programs/research-innovation-system-information/documents/annual-collision-data/2022-crash-data-on-cshwy-book-fixed-v2-a11y.pdf | E5: Rows 1, 3; PDO share | F5: Table extracted from PDF.
B6: S3 | C6: TIMS (UC Berkeley SafeTREC) LA County fatal+injury crash counts 2022-2024, as quoted by secondary sources | D6: https://arashlaw.com/how-many-car-accidents-happen-each-day-in-los-angeles/ ; https://mylawcompany.com/los-angeles-car-accident-lawyer/statistics/ | E6: Row 1 F+I crash count (40,449 in 2022; 40,717 in 2023) | F6: SECONDARY - TIMS requires login; please export the county total from tims.berkeley.edu to confirm.
B7: S4 | C7: Skabardonis, Petty, Noeimi, Rydzewski, Varaiya (1995). Freeway Service Patrol Evaluation (I-880). PATH UCB-ITS-PRR-95-5. | D7: https://escholarship.org/content/qt36r1t2m2/qt36r1t2m2.pdf | E7: Row 1 incident rates (~100/MVM, 4% lane-blocking) and durations | F7: Full text read.
B8: S5 | C8: Crosstown LA (2019). SigAlerts up in Los Angeles (CHP data, 2016-2018). | D8: https://xtown.la/2019/02/06/sigalerts-up-in-los-angeles/ | E8: Row 2 rate | F8: Journalistic compilation of CHP data.
B9: S6 | C9: I-710 Big Rig Freeway Service Patrol evaluation (user's footnote; safehighways.org) | D9: https://safehighways.org/ (user-provided) | E9: Row 2 duration check 58-76 min (secondary in v4) | F9: From user's draft; not re-fetched.
B10: S7 | C10: NHTSA FARS 2020-2024, LA County fatal crashes (user's slide 8 query) | D10: https://crashviewer.nhtsa.dot.gov/CrashAPI | E10: Row 3 rate 952.5/yr | F10: API returned HTTP 403 from sandbox - NOT independently re-run.
B11: S8 | C11: Caltrans quick-clearance / major-incident average clearance time 3 h 8 min (user's footnote; verified in earlier session) | D11: https://dot.ca.gov/ (user-provided) | E11: Row 3 duration cross-check 188 min (secondary in v4) | F11: Verified earlier.
B12: S9 | C12: California OTS Crash Rankings - Los Angeles County 2022 and 2023 | D12: https://www.ots.ca.gov/rankings/los-angeles-county-2022/ ; https://www.ots.ca.gov/rankings/los-angeles-county-2023/ | E12: Victim counts (58,147 in 2022; 58,758 in 2023), DVMT | F12: Fetched.
B13: S10 | C13: Waymo Safety Impact Hub (data through March 2026) | D13: https://waymo.com/safety/impact/ | E13: Rows 4-6 AV/human ratios (LA) | F13: Fetched 23 Sep 2026.
B14: S11 | C14: Kusano et al. (2025). Comparison of Waymo rider-only crash rates by crash type to human benchmarks at 56.7 million miles. Traffic Injury Prevention. | D14: https://www.tandfonline.com/doi/10.1080/15389588.2025.2499887 | E14: Rows 4-6 ratios and CIs | F14: Abstract + prior-session extraction; supplementary CSV not downloaded.
... B65: S57 | C65: Caltrans Facts 2022 booklet (state AVMT by system, 2020) | D65: https://dot.ca.gov/-/media/dot-media/programs/research-innovation-system-information/documents/caltrans-fact-booklets/2022-caltrans-factsv2-a11y.pdf | E65: Context (VMT shares) | F65: Snippet.
